<?xml version="1.0"?>
<!-- Frankenstein: Asimov legs + Atom01 torso/arms -->
<mujoco model="Frankenstein">
    <compiler angle="radian" meshdir="asimov-v0/assets/meshes"/>
    <visual>
        <global offwidth="1920" offheight="1080"/>
    </visual>

    <default>
        <joint frictionloss="0"/>
        <motor ctrlrange="-1 1" ctrllimited="true"/>
        <default class="motor">
            <joint damping="0"/>
        </default>
        <default class="visual">
            <geom material="visual_grey" contype="0" conaffinity="0" group="2"/>
        </default>
        <default class="collision">
            <geom group="3" rgba=".2 .6 .2 .3" type="capsule" contype="1" conaffinity="1"/>
            <default class="foot_capsule">
                <geom type="capsule" size="0.01"/>
            </default>
            <default class="body_capsule">
                <geom type="capsule" size="0.05"/>
            </default>
        </default>
        <default class="arm_joint_param">
            <joint damping="0.01" frictionloss="0.01" armature="0.01"/>
        </default>
    </default>

    <asset>
        <material name="visual_grey" rgba="0.7 0.7 0.7 1.0" />
        <material name="collision_grey" rgba="0.5 0.5 0.5 0.5" />
        <texture type="skybox" builtin="gradient" rgb1="0.3 0.5 0.7" rgb2="0 0 0" width="512" height="512"/>
        <texture name="texplane" type="2d" builtin="checker" rgb1=".2 .3 .4" rgb2=".1 0.15 0.2" width="512" height="512" mark="cross" markrgb=".8 .8 .8"/>
        <material name="groundplane" texture="texplane" texuniform="true" texrepeat="5 5" reflectance="0.2"/>
        <material name="material" rgba="0.75294 0.75294 0.75294 1" />
        
        <!-- Asimov leg meshes -->
        <mesh name="pelvis_link.STL" file="pelvis_link.STL" />
        <mesh name="left_hip_pitch_link.STL" file="left_hip_pitch_link.STL" />
        <mesh name="left_hip_roll_link.STL" file="left_hip_roll_link.STL" />
        <mesh name="left_hip_yaw_link.STL" file="left_hip_yaw_link.STL" />
        <mesh name="left_knee_link.STL" file="left_knee_link.STL" />
        <mesh name="left_ankle_pitch_link.STL" file="left_ankle_pitch_link.STL" />
        <mesh name="left_ankle_roll_link.STL" file="left_ankle_roll_link.STL" />
        <mesh name="left_toe_link.STL" file="left_toe_link.STL" />
        <mesh name="right_hip_pitch_link.STL" file="right_hip_pitch_link.STL" />
        <mesh name="right_hip_roll_link.STL" file="right_hip_roll_link.STL" />
        <mesh name="right_hip_yaw_link.STL" file="right_hip_yaw_link.STL" />
        <mesh name="right_knee_link.STL" file="right_knee_link.STL" />
        <mesh name="right_ankle_pitch_link.STL" file="right_ankle_pitch_link.STL" />
        <mesh name="right_ankle_roll_link.STL" file="right_ankle_roll_link.STL" />
        <mesh name="right_toe_link.STL" file="right_toe_link.STL" />
        
        <!-- Atom01 torso/arm meshes -->
        <mesh name="torso_link" file="../../../roboto-origin/assets/torso_link.STL"/>
        <mesh name="left_arm_pitch_link" file="../../../roboto-origin/assets/left_arm_pitch_link.STL"/>
        <mesh name="left_arm_roll_link" file="../../../roboto-origin/assets/left_arm_roll_link.STL"/>
        <mesh name="left_arm_yaw_link" file="../../../roboto-origin/assets/left_arm_yaw_link.STL"/>
        <mesh name="left_elbow_pitch_link" file="../../../roboto-origin/assets/left_elbow_pitch_link.STL"/>
        <mesh name="left_elbow_yaw_link" file="../../../roboto-origin/assets/left_elbow_yaw_link.STL"/>
        <mesh name="right_arm_pitch_link" file="../../../roboto-origin/assets/right_arm_pitch_link.STL"/>
        <mesh name="right_arm_roll_link" file="../../../roboto-origin/assets/right_arm_roll_link.STL"/>
        <mesh name="right_arm_yaw_link" file="../../../roboto-origin/assets/right_arm_yaw_link.STL"/>
        <mesh name="right_elbow_pitch_link" file="../../../roboto-origin/assets/right_elbow_pitch_link.STL"/>
        <mesh name="right_elbow_yaw_link" file="../../../roboto-origin/assets/right_elbow_yaw_link.STL"/>
        
        <!-- G1 head mesh -->
        <mesh name="head_link.STL" file="../../../misc/meshes/head_link.STL"/>
    </asset>

    <worldbody>
        <light pos="1 0 3.5" dir="0 0 -1" directional="true"/>
        <geom name="floor" size="0 0 0.05" type="plane" material="groundplane" contype="1" conaffinity="1"/>
        <light directional="true" diffuse=".4 .4 .4" specular="0.1 0.1 0.1" pos="0 0 5.0" dir="0 0 -1" castshadow="false" />
        <light directional="true" diffuse=".6 .6 .6" specular="0.2 0.2 0.2" pos="0 0 4" dir="0 0 -1" />

        <body name="pelvis_link" pos="0.00000000 0.00000000 0.739" quat="1 0 0 0">
            <inertial pos="-0.00071228 -3.4719E-07 -0.073826" quat="1.0 0.0 0.0 0.0" mass="3.3125" diaginertia="0.0033117 0.0028238 0.003564" />
            <joint name="floating_base_joint" type="free" limited="false"/>
            <geom name="pelvis_link_collision" pos="0 0 0" quat="1.0 0.0 0.0 0.0" type="mesh" mesh="pelvis_link.STL"/>
            <geom name="pelvis_link_visual" pos="0 0 0" quat="1.0 0.0 0.0 0.0" type="mesh" mesh="pelvis_link.STL" class="visual" />
            <site name="imu_in_pelvis" size="0.01" pos="0.04525 0 -0.08339"/>

            <!-- ASIMOV LEFT LEG -->
            <body name="left_hip_pitch_link" pos="0 0.056569 -0.10543" quat="1.0 0.0 0.0 0.0">
                <joint name="left_hip_pitch_joint" type="hinge" ref="0.0" class="motor" range="-2.094395 1" axis="0 0.70711 -0.70711" armature="0.01"/>
                <inertial pos="0.00329 0.045581 -0.045581" quat="1.0 0.0 0.0 0.0" mass="0.92565" diaginertia="0.00053984 0.00066418 0.00066419" />
                <geom name="left_hip_pitch_link_collision" pos="0 0 0" quat="1.0 0.0 0.0 0.0" class="body_capsule" fromto="0 0 0 0 0.05 -0.05"/>
                <geom name="left_hip_pitch_link_visual" pos="0 0 0" quat="1.0 0.0 0.0 0.0" type="mesh" mesh="left_hip_pitch_link.STL" class="visual" />

                <body name="left_hip_roll_link" pos="0 0.051265 -0.051265" quat="1.0 0.0 0.0 0.0">
                    <joint name="left_hip_roll_joint" type="hinge" ref="0.0" class="motor" range="-0.785398 0.785398" axis="1 0 0" armature="0.01"/>
                    <inertial pos="0.01525 -0.00017964 -0.061059" quat="1.0 0.0 0.0 0.0" mass="0.83528" diaginertia="0.00054401 0.00063585 0.00038113" />
                    <geom name="left_hip_roll_link_visual" pos="0 0 0" quat="1.0 0.0 0.0 0.0"  type="mesh" mesh="left_hip_roll_link.STL" class="visual" />
                    
                    <body name="left_hip_yaw_link" pos="0 0 -0.09275" quat="1.0 0.0 0.0 0.0">
                        <joint name="left_hip_yaw_joint" type="hinge" ref="0.0" class="motor" range="-0.785398 0.785398" axis="0 0 -1" armature="0.01"/>
                        <inertial pos="7.0761E-05 0.00031363 -0.11496" quat="1.0 0.0 0.0 0.0" mass="1.2782" diaginertia="0.0024302 0.0025065 0.0007566" />
                        <geom name="left_hip_yaw_link_collision" pos="0 0 0" quat="1.0 0.0 0.0 0.0" class="body_capsule" fromto="0 0 -0.01 0 0 -0.05"/>
                        <geom name="left_hip_yaw_link_visual" pos="0 0 0" quat="1.0 0.0 0.0 0.0"  type="mesh" mesh="left_hip_yaw_link.STL" class="visual" />

                        <body name="left_knee_link" pos="0 0 -0.15489" quat="1.0 0.0 0.0 0.0">
                            <joint name="left_knee_joint" type="hinge" ref="0.0" class="motor" range="0 1.5" axis="0 1 0" armature="0.01"/>
                            <inertial pos="-0.0025212 0.00051084 -0.10659" quat="1.0 0.0 0.0 0.0" mass="2.2481" diaginertia="0.0093797 0.0095623 0.0023403" />
                            <geom name="left_knee_link_collision" pos="0 0 0" quat="1.0 0.0 0.0 0.0" class="body_capsule" fromto="0 0 0 0 0 -0.25"/>
                            <geom name="left_knee_link_visual" pos="0 0 0" quat="1.0 0.0 0.0 0.0"  type="mesh" mesh="left_knee_link.STL" class="visual" />
                            
                            <body name="left_ankle_pitch_link" pos="0 0 -0.29466" quat="1.0 0.0 0.0 0.0">
                                <joint name="left_ankle_pitch_joint" type="hinge" ref="0.0" class="motor" range="-0.349066 0.5" axis="0 1 0" armature="0.01"/>
                                <inertial pos="-0.0011784 -2.4418E-08 -0.0061736" quat="1.0 0.0 0.0 0.0" mass="0.27369" diaginertia="6.4443e-05 8.1172e-05 4.7493e-05" />
                                <geom name="left_ankle_pitch_link_visual" pos="0 0 0" quat="1.0 0.0 0.0 0.0"  type="mesh" mesh="left_ankle_pitch_link.STL" class="visual" />
                                
                                <body name="left_ankle_roll_link" pos="-0.0015 0 -0.01" quat="1.0 0.0 0.0 0.0">
                                    <joint name="left_ankle_roll_joint" type="hinge" ref="0.0" class="motor" range="-0.1 0.1" axis="-1 0 0" armature="0.01"/>
                                    <inertial pos="0.081381 -0.00033806 -0.015509" quat="1.0 0.0 0.0 0.0" mass="0.61291" diaginertia="0.00031968 0.00045036 0.00070504" />
                                    <geom name="left_ankle_roll_link_visual" pos="0 0 0" quat="1.0 0.0 0.0 0.0" type="mesh" mesh="left_ankle_roll_link.STL" class="visual" />
                                    <site name="left_foot" pos="0.04 0 -0.025"/>
                                    <geom name="left_foot1_collision" class="foot_capsule" fromto="0.06 -0.03 -0.022 0.09 -0.035 -0.022"/>
                                    <geom name="left_foot2_collision" class="foot_capsule" fromto="-0.035 -0.015 -0.022 0.09 -0.015 -0.022"/>
                                    <geom name="left_foot3_collision" class="foot_capsule" fromto="-0.035 0.0 -0.022 0.09 0.0 -0.022"/>
                                    <geom name="left_foot4_collision" class="foot_capsule" fromto="-0.035 0.015 -0.022 0.09 0.015 -0.022"/>
                                    <geom name="left_foot6_collision" class="foot_capsule" fromto="0.0 0.03 -0.022 0.09 0.035 -0.022"/>
                                    
                                    <body name="left_toe_link" pos="0.10253 -0.0043664 -0.0067324" quat="1.0 0.0 0.0 0.0">
                                        <joint name="left_toe_joint" type="hinge" range="-1.047 0" axis="0.010532 0.99994 0" limited="true" stiffness="4.5" springref="0" damping="0.5" armature="0.01" frictionloss="0.02" solreflimit="0.005 1" solimplimit="0.99 0.999 0.001" margin="0.01"/>
                                        <inertial pos="0.0320167773761624 0.000718248511968056 -0.0141312773022902" quat="1.0 0.0 0.0 0.0" mass="0.112221237946844" diaginertia="5.5351925218088e-05 3.65130809524718e-05 8.54029969529202e-05" />
                                        <geom name="left_toe_link_visual" pos="0 0 0" quat="1.0 0.0 0.0 0.0" type="mesh" mesh="left_toe_link.STL" class="visual" />
                                        <geom name="left_toe1_collision" class="foot_capsule" fromto="0.01 -0.03 -0.018 0.04 -0.03 -0.018"/>
                                        <geom name="left_toe2_collision" class="foot_capsule" fromto="0.01 -0.015 -0.018 0.055 -0.015 -0.018"/>
                                        <geom name="left_toe3_collision" class="foot_capsule" fromto="0.01 0.0 -0.018 0.06 0 -0.018"/>
                                        <geom name="left_toe4_collision" class="foot_capsule" fromto="0.01 0.02 -0.018 0.055 0.02 -0.018"/>
                                        <geom name="left_toe5_collision" class="foot_capsule" fromto="0.01 0.04 -0.018 0.04 0.04 -0.018"/>
                                    </body>
                                </body>
                            </body>
                        </body>
                    </body>
                </body>
            </body>

            <!-- ASIMOV RIGHT LEG -->
            <body name="right_hip_pitch_link" pos="0 -0.056569 -0.10543" quat="1.0 0.0 0.0 0.0">
                <inertial pos="0.0032901 -0.045581 -0.045581" quat="1.0 0.0 0.0 0.0" mass="0.92565" diaginertia="0.00053984 0.00066418 0.00066418" />
                <joint name="right_hip_pitch_joint" type="hinge" ref="0.0" class="motor" range="-1 2.094395" axis="0 -0.70711 -0.70711" armature="0.01"/>
                <geom name="right_hip_pitch_link_collision" pos="0 0 0" quat="1.0 0.0 0.0 0.0" class="body_capsule" fromto="0 0 0 0 -0.05 -0.05"/>
                <geom name="right_hip_pitch_link_visual" pos="0 0 0" quat="1.0 0.0 0.0 0.0"  type="mesh" mesh="right_hip_pitch_link.STL" class="visual" />
                
                <body name="right_hip_roll_link" pos="0 -0.051265 -0.051265" quat="1.0 0.0 0.0 0.0">
                    <joint name="right_hip_roll_joint" type="hinge" ref="0.0" class="motor" range="-0.785398 0.785398" axis="1 0 0" armature="0.01"/>
                    <inertial pos="0.01525 0.0001796 -0.061059" quat="1.0 0.0 0.0 0.0" mass="0.83528" diaginertia="0.00054401 0.00063584 0.00038113" />
                    <geom name="right_hip_roll_link_visual" pos="0 0 0" quat="1.0 0.0 0.0 0.0"  type="mesh" mesh="right_hip_roll_link.STL" class="visual" />
                    
                    <body name="right_hip_yaw_link" pos="0 0 -0.09275" quat="1.0 0.0 0.0 0.0">
                        <joint name="right_hip_yaw_joint" type="hinge" ref="0.0" class="motor" range="-0.785398 0.785398" axis="0 0 -1" armature="0.01"/>
                        <inertial pos="7.1067E-05 -0.00031339 -0.11496" quat="1.0 0.0 0.0 0.0" mass="1.2782" diaginertia="0.0024302 0.0025065 0.0007566" />
                        <geom name="right_hip_yaw_link_collision" pos="0 0 0" quat="1.0 0.0 0.0 0.0" class="body_capsule" fromto="0 0 -0.01 0 0 -0.05"/>
                        <geom name="right_hip_yaw_link_visual" pos="0 0 0" quat="1.0 0.0 0.0 0.0"  type="mesh" mesh="right_hip_yaw_link.STL" class="visual" />
                        
                        <body name="right_knee_link" pos="0 0 -0.15489" quat="1.0 0.0 0.0 0.0">
                            <joint name="right_knee_joint" type="hinge" ref="0.0" class="motor" range="-1.5 0" axis="0 -1 0" armature="0.01"/>
                            <inertial pos="-0.0025213 -0.00051098 -0.10659" quat="1.0 0.0 0.0 0.0" mass="2.2481" diaginertia="0.0093796 0.0095623 0.0023403" />
                            <geom name="right_knee_link_collision" pos="0 0 0" quat="1.0 0.0 0.0 0.0" class="body_capsule" fromto="0 0 0 0 0 -0.25"/>
                            <geom name="right_knee_link_visual" pos="0 0 0" quat="1.0 0.0 0.0 0.0"  type="mesh" mesh="right_knee_link.STL" class="visual" />
                            
                            <body name="right_ankle_pitch_link" pos="0 0 -0.29466" quat="1.0 0.0 0.0 0.0">
                                <joint name="right_ankle_pitch_joint" type="hinge" ref="0.0" class="motor" range="-0.5 0.349066" axis="0 -1 0" armature="0.01"/>
                                <inertial pos="-0.0011784 5.9726E-08 -0.0061735" quat="1.0 0.0 0.0 0.0" mass="0.27369" diaginertia="6.4442e-05 8.1171e-05 4.7493e-05" />
                                <geom name="right_ankle_pitch_link_visual" pos="0 0 0" quat="1.0 0.0 0.0 0.0"  type="mesh" mesh="right_ankle_pitch_link.STL" class="visual" />
                                
                                <body name="right_ankle_roll_link" pos="-0.0015 0 -0.01" quat="1.0 0.0 0.0 0.0">
                                    <joint name="right_ankle_roll_joint" type="hinge" ref="0.0" class="motor" range="-0.1 0.1" axis="-1 0 0" armature="0.01"/>
                                    <inertial pos="0.081347 0.00027474 -0.015509" quat="1.0 0.0 0.0 0.0" mass="0.61291" diaginertia="0.0003197 0.00045029 0.00070498" />
                                    <geom name="right_ankle_roll_link_visual" pos="0 0 0" quat="1.0 0.0 0.0 0.0" type="mesh" mesh="right_ankle_roll_link.STL" class="visual" />
                                    <site name="right_foot" pos="0.04 0 -0.025"/>
                                    <geom name="right_foot1_collision" class="foot_capsule" fromto="0.0 -0.03 -0.022 0.09 -0.035 -0.022"/>
                                    <geom name="right_foot2_collision" class="foot_capsule" fromto="-0.035 -0.015 -0.022 0.09 -0.015 -0.022"/>
                                    <geom name="right_foot3_collision" class="foot_capsule" fromto="-0.035 0.0 -0.022 0.09 0.0 -0.022"/>
                                    <geom name="right_foot4_collision" class="foot_capsule" fromto="-0.035 0.015 -0.022 0.09 0.015 -0.022"/>
                                    <geom name="right_foot5_collision" class="foot_capsule" fromto="0.06 0.030 -0.022 0.09 0.035 -0.022"/>
                                    
                                    <body name="right_toe_link" pos="0.10247 0.0042796 -0.0067324" quat="1.0 0.0 0.0 0.0">
                                        <joint name="right_toe_joint" type="hinge" range="0 1.047" axis="0.0074685 -0.99997 0" limited="true" stiffness="4.5" springref="0" damping="0.5" armature="0.01" frictionloss="0.02" solreflimit="0.005 1" solimplimit="0.99 0.999 0.001" margin="0.01"/>
                                        <inertial pos="0.0320141754360937 -0.000816708013105544 -0.0141309094649689" quat="1.0 0.0 0.0 0.0" mass="0.112221754054884" diaginertia="5.5358948695321e-05 3.65052769951383e-05 8.54017357052965e-05" />
                                        <geom name="right_toe_link_visual" pos="0 0 0" quat="1.0 0.0 0.0 0.0" type="mesh" mesh="right_toe_link.STL" class="visual" />
                                        <geom name="right_toe1_collision" class="foot_capsule" fromto="0.01 -0.04 -0.018 0.04 -0.04 -0.018"/>
                                        <geom name="right_toe2_collision" class="foot_capsule" fromto="0.01 -0.02 -0.018 0.055 -0.02 -0.018"/>
                                        <geom name="right_toe3_collision" class="foot_capsule" fromto="0.01 0.0 -0.018 0.06 0 -0.018"/>
                                        <geom name="right_toe4_collision" class="foot_capsule" fromto="0.01 0.015 -0.018 0.055 0.015 -0.018"/>
                                        <geom name="right_toe5_collision" class="foot_capsule" fromto="0.01 0.03 -0.018 0.04 0.03 -0.018"/>
                                    </body>
                                </body>
                            </body>
                        </body>
                    </body>
                </body>
            </body>

            <!-- ATOM01 TORSO AND ARMS -->
            <body name="torso_link" pos="0 0 0">
                <inertial pos="-0.00234775 -0.00000466 0.0984446" mass="7.58189737" fullinertia="0.06904132 0.05679531 0.03888628 -0.00004044 0.00223305 -0.00001881"/>
                <geom type="mesh" rgba="0.752941 0.752941 0.752941 1" mesh="torso_link" class="visual"/>
                
                <!-- G1 Head -->
                <body name="head_link" pos="0 0 -0.09">
                    <inertial pos="0 0 0.05" mass="0.5" diaginertia="0.001 0.001 0.001"/>
                    <geom type="mesh" contype="0" conaffinity="0" group="2" rgba="0.2 0.2 0.2 1" mesh="head_link.STL"/>
                    <geom type="mesh" rgba="0.2 0.2 0.2 1" mesh="head_link.STL"/>
                </body>
                
                <!-- Left arm -->
                <body name="left_arm_pitch_link" pos="0 0.121749999999383 0.206175860782433">
                    <inertial pos="-0.00436523 0.04995146 0.0" mass="0.47284363" fullinertia="0.00015644 0.00008197 0.00018907 0.00002207 0.0 0.0"/>
                    <joint name="left_arm_pitch_joint" pos="0 0 0" axis="0 1 0" range="-3.14 1.57" class="arm_joint_param"/>
                    <geom type="mesh" rgba="0.752941 0.752941 0.752941 1" mesh="left_arm_pitch_link" class="visual"/>
                    
                    <body name="left_arm_roll_link" pos="0.02 0.056 0">
                        <inertial pos="-0.0029007 0.0 -0.02197112" mass="0.08401883" fullinertia="0.00004601 0.00005649 0.00002712 0.0 -0.00001743 0.0"/>
                        <joint name="left_arm_roll_joint" pos="0 0 0" axis="1 0 0" range="-0.25 3.14" class="arm_joint_param"/>
                        <geom type="mesh" rgba="0.752941 0.752941 0.752941 1" mesh="left_arm_roll_link" class="visual"/>
                        
                        <body name="left_arm_yaw_link" pos="-0.02 0 -0.05">
                            <inertial pos="-0.00004328 -0.0018211 -0.10615895" mass="1.15324354" fullinertia="0.00619553 0.00615816 0.0003308 -0.00000002 -0.00000077 -0.0001812"/>
                            <joint name="left_arm_yaw_joint" pos="0 0 0" axis="0 0 -1" range="-2.6 2.6" class="arm_joint_param"/>
                            <geom type="mesh" rgba="0.752941 0.752941 0.752941 1" mesh="left_arm_yaw_link" class="visual"/>
                            
                            <body name="left_elbow_pitch_link" pos="0 0.02 -0.18875">
                                <inertial pos="0.02378501 -0.00433076 0.0" mass="0.09168684" fullinertia="0.00003059 0.00005023 0.00006277 0.00002004 0.0 0.0"/>
                                <joint name="left_elbow_pitch_joint" pos="0 0 0" axis="0 1 0" range="-1 1.57" class="arm_joint_param"/>
                                <geom type="mesh" rgba="0.752941 0.752941 0.752941 1" mesh="left_elbow_pitch_link" class="visual"/>
                                
                                <body name="left_elbow_yaw_link" pos="0.05 -0.02 0">
                                    <inertial pos="0.05317619 -0.0000345 -0.00001992" mass="0.68145595" fullinertia="0.00024481 0.00132562 0.00132647 -0.00000008 -0.00000014 -0.0000006"/>
                                    <joint name="left_elbow_yaw_joint" pos="0 0 0" axis="1 0 0" range="-1.57 1.57" class="arm_joint_param"/>
                                    <geom type="mesh" rgba="0.752941 0.752941 0.752941 1" mesh="left_elbow_yaw_link" class="visual"/>
                                </body>
                            </body>
                        </body>
                    </body>
                </body>
                
                <!-- Right arm -->
                <body name="right_arm_pitch_link" pos="0 -0.12175 0.20518">
                    <inertial pos="-0.00436523 -0.04995146 0.0" mass="0.47284363" fullinertia="0.00015644 0.00008197 0.00018907 -0.00002207 0.0 0.0"/>
                    <joint name="right_arm_pitch_joint" pos="0 0 0" axis="0 1 0" range="-3.14 1.57" class="arm_joint_param"/>
                    <geom type="mesh" rgba="0.752941 0.752941 0.752941 1" mesh="right_arm_pitch_link" class="visual"/>
                    
                    <body name="right_arm_roll_link" pos="0.02 -0.056 0">
                        <inertial pos="-0.0029007 0.0 -0.02197112" mass="0.08401883" fullinertia="0.00004601 0.00005649 0.00002712 0.0 -0.00001743 0.0"/>
                        <joint name="right_arm_roll_joint" pos="0 0 0" axis="1 0 0" range="-3.14 0.25" class="arm_joint_param"/>
                        <geom type="mesh" rgba="0.752941 0.752941 0.752941 1" mesh="right_arm_roll_link" class="visual"/>
                        
                        <body name="right_arm_yaw_link" pos="-0.02 0 -0.05">
                            <inertial pos="-0.00004328 0.0018211 -0.10615895" mass="1.15429959" fullinertia="0.0062043 0.00616498 0.00033199 0.00000007 -0.00000008 0.00017831"/>
                            <joint name="right_arm_yaw_joint" pos="0 0 0" axis="0 0 -1" range="-2.6 2.6" class="arm_joint_param"/>
                            <geom type="mesh" rgba="0.752941 0.752941 0.752941 1" mesh="right_arm_yaw_link" class="visual"/>
                            
                            <body name="right_elbow_pitch_link" pos="0 -0.02 -0.18875">
                                <inertial pos="0.02378501 0.00433076 0.0" mass="0.09168684" fullinertia="0.00003059 0.00005023 0.00006277 -0.00002004 0.0 0.0"/>
                                <joint name="right_elbow_pitch_joint" pos="0 0 0" axis="0 1 0" range="-1.0 1.57" class="arm_joint_param"/>
                                <geom type="mesh" rgba="0.752941 0.752941 0.752941 1" mesh="right_elbow_pitch_link" class="visual"/>
                                
                                <body name="right_elbow_yaw_link" pos="0.05 0.02 0">
                                    <inertial pos="0.05317619 0.0000345 -0.00001992" mass="0.68145595" fullinertia="0.00024481 0.00132562 0.00132647 0.00000008 0.00000014 -0.0000006"/>
                                    <joint name="right_elbow_yaw_joint" pos="0 0 0" axis="1 0 0" range="-1.57 1.57" class="arm_joint_param"/>
                                    <geom type="mesh" rgba="0.752941 0.752941 0.752941 1" mesh="right_elbow_yaw_link" class="visual"/>
                                </body>
                            </body>
                        </body>
                    </body>
                </body>
            </body>
        </body>
    </worldbody>

    <contact>
        <exclude body1="pelvis_link" body2="left_hip_pitch_link" />
        <exclude body1="left_hip_pitch_link" body2="left_hip_roll_link" />
        <exclude body1="left_hip_roll_link" body2="left_hip_yaw_link" />
        <exclude body1="left_hip_yaw_link" body2="left_knee_link" />
        <exclude body1="left_knee_link" body2="left_ankle_pitch_link" />
        <exclude body1="left_ankle_pitch_link" body2="left_ankle_roll_link" />
        <exclude body1="left_ankle_roll_link" body2="left_toe_link" />
        <exclude body1="pelvis_link" body2="right_hip_pitch_link" />
        <exclude body1="right_hip_pitch_link" body2="right_hip_roll_link" />
        <exclude body1="right_hip_roll_link" body2="right_hip_yaw_link" />
        <exclude body1="right_hip_yaw_link" body2="right_knee_link" />
        <exclude body1="right_knee_link" body2="right_ankle_pitch_link" />
        <exclude body1="right_ankle_pitch_link" body2="right_ankle_roll_link" />
        <exclude body1="right_ankle_roll_link" body2="right_toe_link" />
        <exclude body1="pelvis_link" body2="torso_link" />
    </contact>

    <actuator>
        <!-- Leg actuators (Asimov style) -->
        <motor name="left_hip_pitch_joint" gear="80" joint="left_hip_pitch_joint"/>
        <motor name="left_hip_roll_joint" gear="80" joint="left_hip_roll_joint"/>
        <motor name="left_hip_yaw_joint" gear="80" joint="left_hip_yaw_joint"/>
        <motor name="left_knee_joint" gear="120" joint="left_knee_joint"/>
        <motor name="left_ankle_pitch_joint" gear="40" joint="left_ankle_pitch_joint"/>
        <motor name="left_ankle_roll_joint" gear="40" joint="left_ankle_roll_joint"/>
        <motor name="right_hip_pitch_joint" gear="80" joint="right_hip_pitch_joint"/>
        <motor name="right_hip_roll_joint" gear="80" joint="right_hip_roll_joint"/>
        <motor name="right_hip_yaw_joint" gear="80" joint="right_hip_yaw_joint"/>
        <motor name="right_knee_joint" gear="120" joint="right_knee_joint"/>
        <motor name="right_ankle_pitch_joint" gear="40" joint="right_ankle_pitch_joint"/>
        <motor name="right_ankle_roll_joint" gear="40" joint="right_ankle_roll_joint"/>
        
        <!-- Arm actuators (Atom01 style) -->
        <motor name="left_arm_pitch_joint" gear="20" joint="left_arm_pitch_joint"/>
        <motor name="left_arm_roll_joint" gear="20" joint="left_arm_roll_joint"/>
        <motor name="left_arm_yaw_joint" gear="40" joint="left_arm_yaw_joint"/>
        <motor name="left_elbow_pitch_joint" gear="20" joint="left_elbow_pitch_joint"/>
        <motor name="left_elbow_yaw_joint" gear="20" joint="left_elbow_yaw_joint"/>
        <motor name="right_arm_pitch_joint" gear="20" joint="right_arm_pitch_joint"/>
        <motor name="right_arm_roll_joint" gear="20" joint="right_arm_roll_joint"/>
        <motor name="right_arm_yaw_joint" gear="40" joint="right_arm_yaw_joint"/>
        <motor name="right_elbow_pitch_joint" gear="20" joint="right_elbow_pitch_joint"/>
        <motor name="right_elbow_yaw_joint" gear="20" joint="right_elbow_yaw_joint"/>
    </actuator>

    <sensor>
        <gyro name="imu_ang_vel" site="imu_in_pelvis"/>
        <velocimeter name="imu_lin_vel" site="imu_in_pelvis"/>
        <framequat name="imu_quat" objtype="site" objname="imu_in_pelvis"/>
        <subtreeangmom name="root_angmom" body="pelvis_link"/>
    </sensor>

    <visual>
        <headlight diffuse="0.6 0.6 0.6" ambient="0.1 0.1 0.1" specular="0.9 0.9 0.9"/>
        <rgba haze="0.15 0.25 0.35 1"/>
        <global azimuth="-140" elevation="-20"/>
    </visual>
</mujoco>
