<?xml version="1.0"?>
<!-- Modified: Torso and arms only (legs removed) -->
<mujoco model="atom01-torso">
  <compiler angle="radian" meshdir="../assets/" eulerseq="zyx"/>
  <option timestep="0.001" iterations="100" solver="PGS" gravity="0 0 -9.81">
    <flag frictionloss="enable"/>
  </option>
  <size njmax="500" nconmax="100"/>
  <visual>
    <quality shadowsize="4096"/>
    <map znear="0.05"/>
  </visual>
  <default>
    <joint limited="true"/>
    <motor ctrllimited="true"/>
    <geom condim="4" contype="1" conaffinity="15" solref="0.001 2" friction="0.9 0.2 0.2" group="1"/>
    <equality solref="0.001 2"/>
    <default class="visualgeom">
      <geom material="visualgeom" condim="1" contype="0" conaffinity="0"/>
    </default>
    <default class="obstacle">
      <geom material="obstacle" condim="3" contype="1" conaffinity="15"/>
    </default>
    <default class="waist_joint_param">
      <joint damping="0.01" frictionloss="0.01" armature="0.01"/>
    </default>
    <default class="arm_joint_param">
      <joint damping="0.01" frictionloss="0.01" armature="0.01"/>
    </default>
  </default>
  <asset>
    <texture type="skybox" builtin="gradient" rgb1="0.3 0.5 0.7" rgb2="0 0 0" width="512" height="512"/>
    <texture name="texplane" type="2d" builtin="checker" rgb1=".2 .3 .4" rgb2=".1 0.15 0.2" width="512" height="512" mark="cross" markrgb=".8 .8 .8"/>
    <material name="matplane" reflectance="0." texture="texplane" texrepeat="1 1" texuniform="true"/>
    <material name="obstacle" rgba="0.9 0.6 0.2 1"/>
    <material name="visualgeom" rgba="0.5 0.9 0.2 1"/>
    <mesh name="torso_link" file="torso_link.STL"/>
    <mesh name="left_arm_pitch_link" file="left_arm_pitch_link.STL"/>
    <mesh name="left_arm_roll_link" file="left_arm_roll_link.STL"/>
    <mesh name="left_arm_yaw_link" file="left_arm_yaw_link.STL"/>
    <mesh name="left_elbow_pitch_link" file="left_elbow_pitch_link.STL"/>
    <mesh name="left_elbow_yaw_link" file="left_elbow_yaw_link.STL"/>
    <mesh name="right_arm_pitch_link" file="right_arm_pitch_link.STL"/>
    <mesh name="right_arm_roll_link" file="right_arm_roll_link.STL"/>
    <mesh name="right_arm_yaw_link" file="right_arm_yaw_link.STL"/>
    <mesh name="right_elbow_pitch_link" file="right_elbow_pitch_link.STL"/>
    <mesh name="right_elbow_yaw_link" file="right_elbow_yaw_link.STL"/>
  </asset>
  <worldbody>
    <light directional="true" diffuse=".4 .4 .4" specular="0.1 0.1 0.1" pos="0 0 5.0" dir="0 0 -1" castshadow="false"/>
    <light directional="true" diffuse=".6 .6 .6" specular="0.2 0.2 0.2" pos="0 0 4" dir="0 0 -1"/>
    <geom name="ground" type="plane" size="0 0 1" pos="0.001 0 0" quat="1 0 0 0" material="matplane" condim="1" conaffinity="15" group="0"/>
    <body name="torso_link" pos="0 0 0.75">
      <site name="imu" size="0.01" pos="0.0 0 0.0"/>
      <inertial pos="-0.00234775 -0.00000466 0.0984446" mass="7.58189737" fullinertia="0.06904132 0.05679531 0.03888628 -0.00004044 0.00223305 -0.00001881"/>
      <joint name="floating_base_joint" type="free" limited="false"/>
      <geom type="mesh" rgba="0.752941 0.752941 0.752941 1" mesh="torso_link" class="visualgeom"/>
        <body name="left_arm_pitch_link" pos="0 0.121749999999383 0.206175860782433">
          <inertial pos="-0.00436523 0.04995146 0.0" mass="0.47284363" fullinertia="0.00015644 0.00008197 0.00018907 0.00002207 0.0 0.0"/>
          <joint name="left_arm_pitch_joint" pos="0 0 0" axis="0 1 0" range="-3.14 1.57" class="arm_joint_param"/>
          <geom type="mesh" rgba="0.752941 0.752941 0.752941 1" mesh="left_arm_pitch_link" class="visualgeom"/>
          <body name="left_arm_roll_link" pos="0.02 0.056 0">
            <inertial pos="-0.0029007 0.0 -0.02197112" mass="0.08401883" fullinertia="0.00004601 0.00005649 0.00002712 0.0 -0.00001743 0.0"/>
            <joint name="left_arm_roll_joint" pos="0 0 0" axis="1 0 0" range="-0.25 3.14" class="arm_joint_param"/>
            <geom type="mesh" rgba="0.752941 0.752941 0.752941 1" mesh="left_arm_roll_link" class="visualgeom"/>
            <body name="left_arm_yaw_link" pos="-0.02 0 -0.05">
              <inertial pos="-0.00004328 -0.0018211 -0.10615895" mass="1.15324354" fullinertia="0.00619553 0.00615816 0.0003308 -0.00000002 -0.00000077 -0.0001812"/>
              <joint name="left_arm_yaw_joint" pos="0 0 0" axis="0 0 -1" range="-2.6 2.6" class="arm_joint_param"/>
              <geom type="mesh" rgba="0.752941 0.752941 0.752941 1" mesh="left_arm_yaw_link" class="visualgeom"/>
              <body name="left_elbow_pitch_link" pos="0 0.02 -0.18875">
                <inertial pos="0.02378501 -0.00433076 0.0" mass="0.09168684" fullinertia="0.00003059 0.00005023 0.00006277 0.00002004 0.0 0.0"/>
                <joint name="left_elbow_pitch_joint" pos="0 0 0" axis="0 1 0" range="-1 1.57" class="arm_joint_param"/>
                <geom type="mesh" rgba="0.752941 0.752941 0.752941 1" mesh="left_elbow_pitch_link" class="visualgeom"/>
                <body name="left_elbow_yaw_link" pos="0.05 -0.02 0">
                  <inertial pos="0.05317619 -0.0000345 -0.00001992" mass="0.68145595" fullinertia="0.00024481 0.00132562 0.00132647 -0.00000008 -0.00000014 -0.0000006"/>
                  <joint name="left_elbow_yaw_joint" pos="0 0 0" axis="1 0 0" range="-1.57 1.57" class="arm_joint_param"/>
                  <geom type="mesh" rgba="0.752941 0.752941 0.752941 1" mesh="left_elbow_yaw_link" class="visualgeom"/>
                </body>
              </body>
            </body>
          </body>
        </body>
        <body name="right_arm_pitch_link" pos="0 -0.12175 0.20518">
          <inertial pos="-0.00436523 -0.04995146 0.0" mass="0.47284363" fullinertia="0.00015644 0.00008197 0.00018907 -0.00002207 0.0 0.0"/>
          <joint name="right_arm_pitch_joint" pos="0 0 0" axis="0 1 0" range="-3.14 1.57" class="arm_joint_param"/>
          <geom type="mesh" rgba="0.752941 0.752941 0.752941 1" mesh="right_arm_pitch_link" class="visualgeom"/>
          <body name="right_arm_roll_link" pos="0.02 -0.056 0">
            <inertial pos="-0.0029007 0.0 -0.02197112" mass="0.08401883" fullinertia="0.00004601 0.00005649 0.00002712 0.0 -0.00001743 0.0"/>
            <joint name="right_arm_roll_joint" pos="0 0 0" axis="1 0 0" range="-3.14 0.25" class="arm_joint_param"/>
            <geom type="mesh" rgba="0.752941 0.752941 0.752941 1" mesh="right_arm_roll_link" class="visualgeom"/>
            <body name="right_arm_yaw_link" pos="-0.02 0 -0.05">
              <inertial pos="-0.00004328 0.0018211 -0.10615895" mass="1.15429959" fullinertia="0.0062043 0.00616498 0.00033199 0.00000007 -0.00000008 0.00017831"/>
              <joint name="right_arm_yaw_joint" pos="0 0 0" axis="0 0 -1" range="-2.6 2.6" class="arm_joint_param"/>
              <geom type="mesh" rgba="0.752941 0.752941 0.752941 1" mesh="right_arm_yaw_link" class="visualgeom"/>
              <body name="right_elbow_pitch_link" pos="0 -0.02 -0.18875">
                <inertial pos="0.02378501 0.00433076 0.0" mass="0.09168684" fullinertia="0.00003059 0.00005023 0.00006277 -0.00002004 0.0 0.0"/>
                <joint name="right_elbow_pitch_joint" pos="0 0 0" axis="0 1 0" range="-1.0 1.57" class="arm_joint_param"/>
                <geom type="mesh" rgba="0.752941 0.752941 0.752941 1" mesh="right_elbow_pitch_link" class="visualgeom"/>
                <body name="right_elbow_yaw_link" pos="0.05 0.02 0">
                  <inertial pos="0.05317619 0.0000345 -0.00001992" mass="0.68145595" fullinertia="0.00024481 0.00132562 0.00132647 0.00000008 0.00000014 -0.0000006"/>
                  <joint name="right_elbow_yaw_joint" pos="0 0 0" axis="1 0 0" range="-1.57 1.57" class="arm_joint_param"/>
                  <geom type="mesh" rgba="0.752941 0.752941 0.752941 1" mesh="right_elbow_yaw_link" class="visualgeom"/>
                </body>
              </body>
            </body>
          </body>
        </body>
    </body>
  </worldbody>
  <actuator>
    <motor name="left_arm_pitch_joint" joint="left_arm_pitch_joint" gear="1" ctrllimited="true" ctrlrange="-200 200"/>
    <motor name="left_arm_roll_joint" joint="left_arm_roll_joint" gear="1" ctrllimited="true" ctrlrange="-200 200"/>
    <motor name="left_arm_yaw_joint" joint="left_arm_yaw_joint" gear="1" ctrllimited="true" ctrlrange="-200 200"/>
    <motor name="left_elbow_pitch_joint" joint="left_elbow_pitch_joint" gear="1" ctrllimited="true" ctrlrange="-200 200"/>
    <motor name="left_elbow_yaw_joint" joint="left_elbow_yaw_joint" gear="1" ctrllimited="true" ctrlrange="-200 200"/>
    <motor name="right_arm_pitch_joint" joint="right_arm_pitch_joint" gear="1" ctrllimited="true" ctrlrange="-200 200"/>
    <motor name="right_arm_roll_joint" joint="right_arm_roll_joint" gear="1" ctrllimited="true" ctrlrange="-200 200"/>
    <motor name="right_arm_yaw_joint" joint="right_arm_yaw_joint" gear="1" ctrllimited="true" ctrlrange="-200 200"/>
    <motor name="right_elbow_pitch_joint" joint="right_elbow_pitch_joint" gear="1" ctrllimited="true" ctrlrange="-200 200"/>
    <motor name="right_elbow_yaw_joint" joint="right_elbow_yaw_joint" gear="1" ctrllimited="true" ctrlrange="-200 200"/>
  </actuator>
  <sensor>
    <actuatorpos name="left_arm_pitch_p" actuator="left_arm_pitch_joint" user="13"/>
    <actuatorpos name="left_arm_roll_p" actuator="left_arm_roll_joint" user="13"/>
    <actuatorpos name="left_arm_yaw_p" actuator="left_arm_yaw_joint" user="13"/>
    <actuatorpos name="left_elbow_pitch_p" actuator="left_elbow_pitch_joint" user="13"/>
    <actuatorpos name="left_elbow_yaw_p" actuator="left_elbow_yaw_joint" user="13"/>
    <actuatorpos name="right_arm_pitch_p" actuator="right_arm_pitch_joint" user="13"/>
    <actuatorpos name="right_arm_roll_p" actuator="right_arm_roll_joint" user="13"/>
    <actuatorpos name="right_arm_yaw_p" actuator="right_arm_yaw_joint" user="13"/>
    <actuatorpos name="right_elbow_pitch_p" actuator="right_elbow_pitch_joint" user="13"/>
    <actuatorpos name="right_elbow_yaw_p" actuator="right_elbow_yaw_joint" user="13"/>
    <actuatorvel name="left_arm_pitch_v" actuator="left_arm_pitch_joint" user="13"/>
    <actuatorvel name="left_arm_roll_v" actuator="left_arm_roll_joint" user="13"/>
    <actuatorvel name="left_arm_yaw_v" actuator="left_arm_yaw_joint" user="13"/>
    <actuatorvel name="left_elbow_pitch_v" actuator="left_elbow_pitch_joint" user="13"/>
    <actuatorvel name="left_elbow_yaw_v" actuator="left_elbow_yaw_joint" user="13"/>
    <actuatorvel name="right_arm_pitch_v" actuator="right_arm_pitch_joint" user="13"/>
    <actuatorvel name="right_arm_roll_v" actuator="right_arm_roll_joint" user="13"/>
    <actuatorvel name="right_arm_yaw_v" actuator="right_arm_yaw_joint" user="13"/>
    <actuatorvel name="right_elbow_pitch_v" actuator="right_elbow_pitch_joint" user="13"/>
    <actuatorvel name="right_elbow_yaw_v" actuator="right_elbow_yaw_joint" user="13"/>
    <actuatorfrc name="left_arm_pitch_f" actuator="left_arm_pitch_joint" user="13" noise="1e-3"/>
    <actuatorfrc name="left_arm_roll_f" actuator="left_arm_roll_joint" user="13" noise="1e-3"/>
    <actuatorfrc name="left_arm_yaw_f" actuator="left_arm_yaw_joint" user="13" noise="1e-3"/>
    <actuatorfrc name="left_elbow_pitch_f" actuator="left_elbow_pitch_joint" user="13" noise="1e-3"/>
    <actuatorfrc name="left_elbow_yaw_f" actuator="left_elbow_yaw_joint" user="13" noise="1e-3"/>
    <actuatorfrc name="right_arm_pitch_f" actuator="right_arm_pitch_joint" user="13" noise="1e-3"/>
    <actuatorfrc name="right_arm_roll_f" actuator="right_arm_roll_joint" user="13" noise="1e-3"/>
    <actuatorfrc name="right_arm_yaw_f" actuator="right_arm_yaw_joint" user="13" noise="1e-3"/>
    <actuatorfrc name="right_elbow_pitch_f" actuator="right_elbow_pitch_joint" user="13" noise="1e-3"/>
    <actuatorfrc name="right_elbow_yaw_f" actuator="right_elbow_yaw_joint" user="13" noise="1e-3"/>
    <framequat name="orientation" objtype="site" noise="0.001" objname="imu"/>
    <framepos name="position" objtype="site" noise="0.001" objname="imu"/>
    <gyro name="angular-velocity" site="imu" noise="0.005" cutoff="34.9"/>
    <velocimeter name="linear-velocity" site="imu" noise="0.001" cutoff="30"/>
    <accelerometer name="linear-acceleration" site="imu" noise="0.005" cutoff="157"/>
    <magnetometer name="magnetometer" site="imu"/>
  </sensor>
  <visual>
    <global offwidth="1920" offheight="1080"/>
  </visual>
</mujoco>
