<?xml version="1.0" ?>
<!-- Generated using onshape-to-robot -->
<!-- Onshape document_id: fc6443b1d89dcba950e85b60 -->
<!-- Modified: Torso and arms only (legs removed) -->
<mujoco model="berkeley-humanoid-lite-torso">
  <compiler angle="radian" meshdir="../assets" autolimits="true"/>
  <default>
    <default class="berkeley-humanoid-lite">
      <joint frictionloss="0.1" armature="0.005"/>
      <position kp="50" dampratio="1"/>
      <default class="visual">
        <geom type="mesh" contype="0" conaffinity="0" group="2"/>
      </default>
      <default class="collision">
        <geom group="3"/>
      </default>
    </default>
  </default>
  <worldbody>
    <!-- Link base -->
    <body name="base" pos="0 0 0" quat="1 0 0 0" childclass="berkeley-humanoid-lite">
      <freejoint name="base_freejoint"/>
      <inertial pos="-0.0030965 0.000264765 0.675059" mass="4.44401" fullinertia="0.0667167 0.0447686 0.0318661 1.21502e-06 -0.00131643 2.88151e-05"/>
      <!-- Part base_parts -->
      <geom class="collision" pos="-6.93889e-18 7.53521e-18 0.71" quat="0.707107 -2.07306e-15 1.88738e-15 -0.707107" type="box" size="0.075 0.07 0.115"/>
      <geom type="mesh" class="visual" pos="-0.0030965 0.000264765 0.675059" quat="1 0 0 0" mesh="base_visual_no_hip" material="base_visual_material"/>
      <!-- Link imu_2 -->
      <body name="imu_2" pos="0.061722 -5.97549e-17 0.68" quat="1 -0 5.77316e-15 -6.03078e-16">
        <!-- Joint from base to imu_2 -->
        <!-- Joint is "fixed", skipping it -->
        <inertial pos="3.00866e-18 9.72026e-19 0.0025" mass="0.00197704" fullinertia="1.11441e-07 4.06118e-08 1.43815e-07 -1.67651e-38 0 1.10203e-39"/>
        <!-- Part imu_2_parts -->
        <geom type="mesh" class="visual" pos="0 9.72026e-19 0.0025" quat="1 -0 -5.44009e-15 6.03078e-16" mesh="imu_2_visual" material="imu_2_visual_material"/>
        <!-- Frame imu -->
        <site group="3" name="imu" pos="0 -6.33816e-19 0.005" quat="1 0 0 0"/>
      </body>
      <!-- Link arm_left_shoulder_pitch -->
      <body name="arm_left_shoulder_pitch" pos="5.0759e-15 0.133 0.764028" quat="0.707107 -0.707107 4.44089e-15 4.89969e-15">
        <!-- Joint from base to arm_left_shoulder_pitch -->
        <joint axis="0 0 1" name="arm_left_shoulder_pitch_joint" type="hinge" range="-1.5707963267948983 0.7853981633974465"/>
        <inertial pos="-0.00661228 -8.80749e-05 0.0396144" mass="0.342876" fullinertia="0.000218285 0.000260325 0.00022463 -1.17021e-06 1.05191e-05 -4.52438e-07"/>
        <!-- Part arm_left_shoulder_pitch_parts -->
        <geom type="mesh" class="visual" pos="-0.00661228 -8.80749e-05 0.0396144" quat="0.707107 0.707107 -4.44089e-15 -4.89969e-15" mesh="arm_left_shoulder_pitch_visual" material="arm_left_shoulder_pitch_visual_material"/>
        <!-- Link arm_left_shoulder_roll -->
        <body name="arm_left_shoulder_roll" pos="0.0255 -8.88178e-16 0.043" quat="0.701057 0.092296 0.701057 0.092296">
          <!-- Joint from arm_left_shoulder_pitch to arm_left_shoulder_roll -->
          <joint axis="0 0 1" name="arm_left_shoulder_roll_joint" type="hinge" range="-0.26179938779914025 1.3089969389957563"/>
          <inertial pos="-4.00762e-05 0.0737019 -0.0277329" mass="0.443945" fullinertia="0.000698118 0.000365437 0.000568315 -4.07105e-07 -1.31045e-07 -1.56428e-05"/>
          <!-- Part arm_left_shoulder_roll_parts -->
          <geom type="mesh" class="visual" pos="-4.00762e-05 0.0737019 -0.0277329" quat="0.560986 0.430459 -0.560986 0.430459" mesh="arm_left_shoulder_roll_visual" material="arm_left_shoulder_roll_visual_material"/>
          <!-- Link arm_left_shoulder_yaw -->
          <body name="arm_left_shoulder_yaw" pos="2.55351e-14 0.123 -0.0255" quat="0.707107 -0.707107 2.05835e-13 2.14573e-13">
            <!-- Joint from arm_left_shoulder_roll to arm_left_shoulder_yaw -->
            <joint axis="0 0 1" name="arm_left_shoulder_yaw_joint" type="hinge" range="-0.7853981633969989 0.7853981633978977"/>
            <inertial pos="-0.00781722 -9.17114e-05 0.0409759" mass="0.329199" fullinertia="0.000196136 0.000241556 0.000214842 -1.164e-06 8.20811e-06 -4.93374e-07"/>
            <!-- Part arm_left_shoulder_yaw_parts -->
            <geom class="collision" pos="4.84682e-15 -4.92981e-15 -0.035" quat="6.90541e-14 -5.50948e-15 1 -7.03894e-14" type="cylinder" size="0.04 0.075"/>
            <geom type="mesh" class="visual" pos="-0.00781722 -9.17114e-05 0.0409759" quat="0.092296 0.701057 -0.701057 -0.092296" mesh="arm_left_shoulder_yaw_visual" material="arm_left_shoulder_yaw_visual_material"/>
            <!-- Link arm_left_elbow_pitch -->
            <body name="arm_left_elbow_pitch" pos="0.0245 1.98644e-15 0.043" quat="0.5 0.5 0.5 0.5">
              <!-- Joint from arm_left_shoulder_yaw to arm_left_elbow_pitch -->
              <joint axis="0 0 1" name="arm_left_elbow_pitch_joint" type="hinge" range="-4.4941828036826337e-13 1.5707963267944471"/>
              <inertial pos="-4.00762e-05 0.0737019 -0.0277329" mass="0.443945" fullinertia="0.000698118 0.000365437 0.000568315 -4.07105e-07 -1.31045e-07 -1.56428e-05"/>
              <!-- Part arm_left_elbow_pitch_parts -->
              <geom type="mesh" class="visual" pos="-4.00762e-05 0.0737019 -0.0277329" quat="1.07197e-13 2.03769e-13 0.793353 -0.608761" mesh="arm_left_elbow_pitch_visual" material="arm_left_elbow_pitch_visual_material"/>
              <!-- Link arm_left_elbow_roll -->
              <body name="arm_left_elbow_roll" pos="-2.78536e-14 0.123 -0.0255" quat="0.707107 -0.707107 4.34097e-14 1.78266e-13">
                <!-- Joint from arm_left_elbow_pitch to arm_left_elbow_roll -->
                <joint axis="0 0 1" name="arm_left_elbow_roll_joint" type="hinge" range="-0.7853981633974731 0.7853981633974234"/>
                <inertial pos="-6.0299e-19 -1.64296e-17 0.005" mass="0.000826239" fullinertia="1.20493e-08 1.20493e-08 1.0328e-08 3.60416e-36 9.26493e-38 -1.64865e-25"/>
                <!-- Part arm_left_elbow_roll_parts -->
                <geom class="collision" pos="-6.74047e-19 -7.68244e-18 -0.01" quat="0 1 0 0" type="cylinder" size="0.03 0.06"/>
                <geom type="mesh" class="visual" pos="-6.0299e-19 0 0.005" quat="1.42292e-13 -3.87806e-13 -0.991445 -0.130526" mesh="arm_left_elbow_roll_visual" material="arm_left_elbow_roll_visual_material"/>
                <!-- Link arm_left_hand_link -->
                <body name="arm_left_hand_link" pos="-2.68213e-29 0 -5.55112e-17" quat="1.36181e-15 0.707107 -0.707107 -3.70012e-15">
                  <!-- Joint from arm_left_elbow_roll to arm_left_hand_link -->
                  <!-- Joint is "fixed", skipping it -->
                  <inertial pos="-0.00248666 0.0134979 -0.0541316" mass="0.291741" fullinertia="0.000556491 0.000494025 0.000161723 3.82363e-06 -2.67254e-06 -0.000102102"/>
                  <!-- Part arm_left_hand_link_parts -->
                  <geom type="mesh" class="visual" pos="-0.00248666 0.0134979 -0.0541316" quat="0.701057 -0.092296 -0.092296 0.701057" mesh="arm_left_hand_link_visual" material="arm_left_hand_link_visual_material"/>
                </body>
              </body>
            </body>
          </body>
        </body>
      </body>
      <!-- Link arm_right_shoulder_pitch -->
      <body name="arm_right_shoulder_pitch" pos="1.19187e-16 -0.133 0.764028" quat="2.71137e-15 4.60842e-15 -0.707107 0.707107">
        <!-- Joint from base to arm_right_shoulder_pitch -->
        <joint axis="0 0 1" name="arm_right_shoulder_pitch_joint" type="hinge" range="-0.7853981633975158 1.570796326794829"/>
        <inertial pos="0.00661228 -1.57066e-05 0.0397088" mass="0.342876" fullinertia="0.000218503 0.000260541 0.000224632 2.55599e-07 -1.17928e-05 5.72405e-07"/>
        <!-- Part arm_right_shoulder_pitch_parts -->
        <geom type="mesh" class="visual" pos="0.00661228 -1.57066e-05 0.0397088" quat="2.6975e-15 -4.59801e-15 0.707107 -0.707107" mesh="arm_right_shoulder_pitch_visual" material="arm_right_shoulder_pitch_visual_material"/>
        <!-- Link arm_right_shoulder_roll -->
        <body name="arm_right_shoulder_roll" pos="-0.0255 3.10862e-15 0.043" quat="0.701057 0.092296 -0.701057 -0.092296">
          <!-- Joint from arm_right_shoulder_pitch to arm_right_shoulder_roll -->
          <joint axis="0 0 1" name="arm_right_shoulder_roll_joint" type="hinge" range="-1.308996938995632 0.2617993877992646"/>
          <inertial pos="-4.00762e-05 0.0737019 -0.0277329" mass="0.443945" fullinertia="0.000698118 0.000365437 0.000568315 -4.07105e-07 -1.31045e-07 -1.56428e-05"/>
          <!-- Part arm_right_shoulder_roll_parts -->
          <geom type="mesh" class="visual" pos="-4.00762e-05 0.0737019 -0.0277329" quat="0.430459 0.560986 -0.430459 0.560986" mesh="arm_right_shoulder_roll_visual" material="arm_right_shoulder_roll_visual_material"/>
          <!-- Link arm_right_shoulder_yaw -->
          <body name="arm_right_shoulder_yaw" pos="9.4369e-15 0.123 -0.0255" quat="1.95469e-14 -1.01469e-13 -0.707107 -0.707107">
            <!-- Joint from arm_right_shoulder_roll to arm_right_shoulder_yaw -->
            <joint axis="0 0 1" name="arm_right_shoulder_yaw_joint" type="hinge" range="-0.78539816339745 0.7853981633974465"/>
            <inertial pos="-0.00781722 -1.63693e-05 0.0404875" mass="0.329199" fullinertia="0.000195409 0.000240827 0.000214844 -2.54474e-07 1.84257e-06 -5.40945e-07"/>
            <!-- Part arm_right_shoulder_yaw_parts -->
            <geom class="collision" pos="-1.58554e-15 4.04401e-16 -0.035" quat="5.76054e-15 -1 -1.69636e-14 2.26551e-14" type="cylinder" size="0.04 0.075"/>
            <geom type="mesh" class="visual" pos="-0.00781722 -1.63693e-05 0.0404875" quat="0.092296 -0.701057 -0.701057 0.092296" mesh="arm_right_shoulder_yaw_visual" material="arm_right_shoulder_yaw_visual_material"/>
            <!-- Link arm_right_elbow_pitch -->
            <body name="arm_right_elbow_pitch" pos="0.0245 6.93211e-15 0.043" quat="0.5 0.5 0.5 0.5">
              <!-- Joint from arm_right_shoulder_yaw to arm_right_elbow_pitch -->
              <joint axis="0 0 1" name="arm_right_elbow_pitch_joint" type="hinge" range="-1.5707963267948966 -0.0"/>
              <inertial pos="-4.00762e-05 0.0737019 -0.0277329" mass="0.443945" fullinertia="0.000698118 0.000365437 0.000568315 -4.07105e-07 -1.31045e-07 -1.56428e-05"/>
              <!-- Part arm_right_elbow_pitch_parts -->
              <geom type="mesh" class="visual" pos="-4.00762e-05 0.0737019 -0.0277329" quat="0.608761 0.793353 -5.70655e-14 2.24372e-14" mesh="arm_right_elbow_pitch_visual" material="arm_right_elbow_pitch_visual_material"/>
              <!-- Link arm_right_elbow_roll -->
              <body name="arm_right_elbow_roll" pos="2.87116e-14 0.123 -0.0255" quat="1.88738e-15 4.70586e-15 -0.707107 -0.707107">
                <!-- Joint from arm_right_elbow_pitch to arm_right_elbow_roll -->
                <joint axis="0 0 1" name="arm_right_elbow_roll_joint" type="hinge" range="-0.7853981633974625 0.7853981633974341"/>
                <inertial pos="-6.0299e-19 -1.89849e-17 0.005" mass="0.000826239" fullinertia="1.20493e-08 1.20493e-08 1.0328e-08 -1.40849e-37 -4.81133e-39 6.41982e-25"/>
                <!-- Part arm_right_elbow_roll_parts -->
                <geom class="collision" pos="-6.74047e-19 -2.90123e-17 -0.01" quat="0 1 0 0" type="cylinder" size="0.03 0.06"/>
                <geom type="mesh" class="visual" pos="-6.0299e-19 0 0.005" quat="2.93376e-14 5.49187e-14 0.991445 -0.130526" mesh="arm_right_elbow_roll_visual" material="arm_right_elbow_roll_visual_material"/>
                <!-- Link arm_right_hand_link -->
                <body name="arm_right_hand_link" pos="-6.74047e-19 5.55112e-17 0" quat="7.16041e-15 -0.707107 0.707107 7.3068e-15">
                  <!-- Joint from arm_right_elbow_roll to arm_right_hand_link -->
                  <!-- Joint is "fixed", skipping it -->
                  <inertial pos="-0.00248666 0.0134979 -0.0541316" mass="0.291741" fullinertia="0.000556491 0.000494025 0.000161723 3.82363e-06 -2.67254e-06 -0.000102102"/>
                  <!-- Part arm_right_hand_link_parts -->
                  <geom type="mesh" class="visual" pos="-0.00248666 0.0134979 -0.0541316" quat="0.701057 0.092296 0.092296 0.701057" mesh="arm_right_hand_link_visual" material="arm_right_hand_link_visual_material"/>
                </body>
              </body>
            </body>
          </body>
        </body>
      </body>
    </body>
  </worldbody>
  <asset>
    <mesh file="merged/arm_left_elbow_pitch_visual.stl"/>
    <mesh file="merged/arm_left_shoulder_roll_visual.stl"/>
    <mesh file="merged/arm_left_shoulder_pitch_visual.stl"/>
    <mesh file="merged/arm_right_elbow_pitch_visual.stl"/>
    <mesh file="merged/arm_right_shoulder_yaw_visual.stl"/>
    <mesh file="merged/arm_right_elbow_roll_visual.stl"/>
    <mesh file="merged/arm_right_hand_link_visual.stl"/>
    <mesh file="merged/base_visual_no_hip.stl"/>
    <mesh file="merged/arm_right_shoulder_roll_visual.stl"/>
    <mesh file="merged/arm_left_hand_link_visual.stl"/>
    <mesh file="merged/arm_left_elbow_roll_visual.stl"/>
    <mesh file="merged/arm_left_shoulder_yaw_visual.stl"/>
    <mesh file="merged/arm_right_shoulder_pitch_visual.stl"/>
    <mesh file="merged/imu_2_visual.stl"/>
    <material name="base_visual_material" rgba="0.618701 0.618701 0.618701 0.773376"/>
    <material name="imu_2_visual_material" rgba="0.8 0.8 0.8 1"/>
    <material name="arm_left_shoulder_pitch_visual_material" rgba="0.521528 0.521528 0.521528 0.65191"/>
    <material name="arm_left_shoulder_roll_visual_material" rgba="0.584926 0.584926 0.584926 0.731157"/>
    <material name="arm_left_shoulder_yaw_visual_material" rgba="0.509959 0.509959 0.509959 0.637449"/>
    <material name="arm_left_elbow_pitch_visual_material" rgba="0.584926 0.584926 0.584926 0.731157"/>
    <material name="arm_left_elbow_roll_visual_material" rgba="0.8 0.8 0.8 1"/>
    <material name="arm_left_hand_link_visual_material" rgba="0.8 0.8 0.8 1"/>
    <material name="arm_right_shoulder_pitch_visual_material" rgba="0.521528 0.521528 0.521528 0.65191"/>
    <material name="arm_right_shoulder_roll_visual_material" rgba="0.584926 0.584926 0.584926 0.731157"/>
    <material name="arm_right_shoulder_yaw_visual_material" rgba="0.509959 0.509959 0.509959 0.637449"/>
    <material name="arm_right_elbow_pitch_visual_material" rgba="0.584926 0.584926 0.584926 0.731157"/>
    <material name="arm_right_elbow_roll_visual_material" rgba="0.8 0.8 0.8 1"/>
    <material name="arm_right_hand_link_visual_material" rgba="0.8 0.8 0.8 1"/>
  </asset>
  <actuator>
    <motor class="berkeley-humanoid-lite" name="arm_left_shoulder_pitch_joint" joint="arm_left_shoulder_pitch_joint" forcerange="-20 20"/>
    <motor class="berkeley-humanoid-lite" name="arm_left_shoulder_roll_joint" joint="arm_left_shoulder_roll_joint" forcerange="-20 20"/>
    <motor class="berkeley-humanoid-lite" name="arm_left_shoulder_yaw_joint" joint="arm_left_shoulder_yaw_joint" forcerange="-20 20"/>
    <motor class="berkeley-humanoid-lite" name="arm_left_elbow_pitch_joint" joint="arm_left_elbow_pitch_joint" forcerange="-20 20"/>
    <motor class="berkeley-humanoid-lite" name="arm_left_elbow_roll_joint" joint="arm_left_elbow_roll_joint" forcerange="-20 20"/>
    <motor class="berkeley-humanoid-lite" name="arm_right_shoulder_pitch_joint" joint="arm_right_shoulder_pitch_joint" forcerange="-20 20"/>
    <motor class="berkeley-humanoid-lite" name="arm_right_shoulder_roll_joint" joint="arm_right_shoulder_roll_joint" forcerange="-20 20"/>
    <motor class="berkeley-humanoid-lite" name="arm_right_shoulder_yaw_joint" joint="arm_right_shoulder_yaw_joint" forcerange="-20 20"/>
    <motor class="berkeley-humanoid-lite" name="arm_right_elbow_pitch_joint" joint="arm_right_elbow_pitch_joint" forcerange="-20 20"/>
    <motor class="berkeley-humanoid-lite" name="arm_right_elbow_roll_joint" joint="arm_right_elbow_roll_joint" forcerange="-20 20"/>
  </actuator>

  <sensor>
    <jointpos name="arm_left_shoulder_pitch_pos"  joint="arm_left_shoulder_pitch_joint"/>
    <jointpos name="arm_left_shoulder_roll_pos"   joint="arm_left_shoulder_roll_joint"/>
    <jointpos name="arm_left_shoulder_yaw_pos"    joint="arm_left_shoulder_yaw_joint"/>
    <jointpos name="arm_left_elbow_pitch_pos"     joint="arm_left_elbow_pitch_joint"/>
    <jointpos name="arm_left_elbow_roll_pos"      joint="arm_left_elbow_roll_joint"/>
    <jointpos name="arm_right_shoulder_pitch_pos" joint="arm_right_shoulder_pitch_joint"/>
    <jointpos name="arm_right_shoulder_roll_pos"  joint="arm_right_shoulder_roll_joint"/>
    <jointpos name="arm_right_shoulder_yaw_pos"   joint="arm_right_shoulder_yaw_joint"/>
    <jointpos name="arm_right_elbow_pitch_pos"    joint="arm_right_elbow_pitch_joint"/>
    <jointpos name="arm_right_elbow_roll_pos"     joint="arm_right_elbow_roll_joint"/>

    <jointvel name="arm_left_shoulder_pitch_vel"  joint="arm_left_shoulder_pitch_joint"/>
    <jointvel name="arm_left_shoulder_roll_vel"   joint="arm_left_shoulder_roll_joint"/>
    <jointvel name="arm_left_shoulder_yaw_vel"    joint="arm_left_shoulder_yaw_joint"/>
    <jointvel name="arm_left_elbow_pitch_vel"     joint="arm_left_elbow_pitch_joint"/>
    <jointvel name="arm_left_elbow_roll_vel"      joint="arm_left_elbow_roll_joint"/>
    <jointvel name="arm_right_shoulder_pitch_vel" joint="arm_right_shoulder_pitch_joint"/>
    <jointvel name="arm_right_shoulder_roll_vel"  joint="arm_right_shoulder_roll_joint"/>
    <jointvel name="arm_right_shoulder_yaw_vel"   joint="arm_right_shoulder_yaw_joint"/>
    <jointvel name="arm_right_elbow_pitch_vel"    joint="arm_right_elbow_pitch_joint"/>
    <jointvel name="arm_right_elbow_roll_vel"     joint="arm_right_elbow_roll_joint"/>

    <jointactuatorfrc name="arm_left_shoulder_pitch_torque"   joint="arm_left_shoulder_pitch_joint"/>
    <jointactuatorfrc name="arm_left_shoulder_roll_torque"    joint="arm_left_shoulder_roll_joint"/>
    <jointactuatorfrc name="arm_left_shoulder_yaw_torque"     joint="arm_left_shoulder_yaw_joint"/>
    <jointactuatorfrc name="arm_left_elbow_pitch_torque"      joint="arm_left_elbow_pitch_joint"/>
    <jointactuatorfrc name="arm_left_elbow_roll_torque"       joint="arm_left_elbow_roll_joint"/>
    <jointactuatorfrc name="arm_right_shoulder_pitch_torque"  joint="arm_right_shoulder_pitch_joint"/>
    <jointactuatorfrc name="arm_right_shoulder_roll_torque"   joint="arm_right_shoulder_roll_joint"/>
    <jointactuatorfrc name="arm_right_shoulder_yaw_torque"    joint="arm_right_shoulder_yaw_joint"/>
    <jointactuatorfrc name="arm_right_elbow_pitch_torque"     joint="arm_right_elbow_pitch_joint"/>
    <jointactuatorfrc name="arm_right_elbow_roll_torque"      joint="arm_right_elbow_roll_joint"/>

    <framequat name="imu_quat" objtype="site" objname="imu" />
    <gyro name="imu_gyro" site="imu" />
    <accelerometer name="imu_acc" site="imu" />
    <framepos name="frame_pos" objtype="site" objname="imu" />
    <framelinvel name="frame_vel" objtype="site" objname="imu" />
  </sensor>
  <equality/>
</mujoco>
