<mujoco model="Asimov">
  <compiler angle="radian" meshdir="../assets/meshes/"/>

  <visual>
    <global azimuth="-140" elevation="-20" offwidth="1920" offheight="1080"/>
    <headlight diffuse="0.6 0.6 0.6" specular="0.9 0.9 0.9"/>
    <rgba haze="0.15 0.25 0.35 1"/>
  </visual>

  <default>
    <default class="motor"/>
    <default class="visual">
      <geom contype="0" conaffinity="0" group="2" material="visual_grey"/>
    </default>
    <default class="collision">
      <geom type="capsule" group="3" rgba="0.2 0.6 0.2 0.3"/>
      <default class="foot_capsule">
        <geom size="0.01 0 0"/>
      </default>
      <default class="body_capsule">
        <geom size="0.05 0 0"/>
      </default>
    </default>
  </default>

  <asset>
    <texture type="skybox" colorspace="auto" builtin="flat" rgb1="0 0 0" rgb2="0 0 0" width="512" height="3072"/>
    <texture type="2d" colorspace="auto" name="groundplane" builtin="checker" mark="edge" rgb1="0.2 0.3 0.4" rgb2="0.1 0.2 0.3" markrgb="0.8 0.8 0.8" width="300" height="300"/>
    <texture type="skybox" colorspace="auto" builtin="gradient" rgb1="0.3 0.5 0.7" rgb2="0 0 0" width="512" height="3072"/>
    <texture type="2d" colorspace="auto" name="texplane" builtin="checker" mark="cross" rgb1="0.2 0.3 0.4" rgb2="0.1 0.15 0.2" markrgb="0.8 0.8 0.8" width="512" height="512"/>
    <material name="visual_grey" rgba="0.7 0.7 0.7 1"/>
    <material name="collision_grey" rgba="0.5 0.5 0.5 0.5"/>
    <material name="groundplane" texture="groundplane" texuniform="true" texrepeat="5 5" reflectance="0.2"/>
    <material name="material" rgba="0.75294 0.75294 0.75294 1"/>
    <material name="collision_material" rgba="1 0.28 0.1 0.9"/>
    <mesh name="pelvis_link.STL" content_type="model/stl" file="pelvis_link.STL"/>
    <mesh name="left_hip_pitch_link.STL" content_type="model/stl" file="left_hip_pitch_link.STL"/>
    <mesh name="left_hip_roll_link.STL" content_type="model/stl" file="left_hip_roll_link.STL"/>
    <mesh name="left_hip_yaw_link.STL" content_type="model/stl" file="left_hip_yaw_link.STL"/>
    <mesh name="left_knee_link.STL" content_type="model/stl" file="left_knee_link.STL"/>
    <mesh name="left_ankle_pitch_link.STL" content_type="model/stl" file="left_ankle_pitch_link.STL"/>
    <mesh name="left_ankle_roll_link.STL" content_type="model/stl" file="left_ankle_roll_link.STL"/>
    <mesh name="left_toe_link.STL" content_type="model/stl" file="left_toe_link.STL"/>
    <mesh name="right_hip_pitch_link.STL" content_type="model/stl" file="right_hip_pitch_link.STL"/>
    <mesh name="right_hip_roll_link.STL" content_type="model/stl" file="right_hip_roll_link.STL"/>
    <mesh name="right_hip_yaw_link.STL" content_type="model/stl" file="right_hip_yaw_link.STL"/>
    <mesh name="right_knee_link.STL" content_type="model/stl" file="right_knee_link.STL"/>
    <mesh name="right_ankle_pitch_link.STL" content_type="model/stl" file="right_ankle_pitch_link.STL"/>
    <mesh name="right_ankle_roll_link.STL" content_type="model/stl" file="right_ankle_roll_link.STL"/>
    <mesh name="right_toe_link.STL" content_type="model/stl" file="right_toe_link.STL"/>
  </asset>

  <worldbody>
    <geom name="floor" size="0 0 0.05" type="plane" material="groundplane"/>
    <light pos="1 0 3.5" dir="0 0 -1" type="directional"/>
    <light pos="0 0 5" dir="0 0 -1" type="directional" castshadow="false" diffuse="0.4 0.4 0.4" specular="0.1 0.1 0.1"/>
    <light pos="0 0 4" dir="0 0 -1" type="directional" diffuse="0.6 0.6 0.6" specular="0.2 0.2 0.2"/>
    <body name="pelvis_link" pos="0 0 0.739">
      <inertial pos="-0.00071228 -3.4719e-07 -0.073826" mass="3.3125" diaginertia="0.0033117 0.0028238 0.003564"/>
      <joint name="floating_base_joint" type="free"/>
      <geom name="pelvis_link_collision" type="mesh" mesh="pelvis_link.STL"/>
      <geom name="pelvis_link_visual" class="visual" type="mesh" mesh="pelvis_link.STL"/>
      <site name="imu_in_pelvis" pos="0.04525 0 -0.08339" size="0.01"/>
      <site name="pelvis_link_site" pos="0 0 0"/>
      <camera name="front_camera" pos="0 2 0.5" quat="0 0 0.707107 0.707107" mode="track" fovy="90"/>
      <camera name="side_camera" pos="-2 0 0.5" quat="-0.5 -0.5 0.5 0.5" mode="track" fovy="90"/>
      <body name="left_hip_pitch_link" pos="0 0.056569 -0.10543">
        <inertial pos="0.00329 0.045581 -0.045581" mass="0.92565" diaginertia="0.00053984 0.00066418 0.00066419"/>
        <joint name="left_hip_pitch_joint" class="motor" pos="0 0 0" axis="0 0.707107 -0.707107" range="-2.0944 1" armature="0.01"/>
        <geom name="left_hip_pitch_link_collision" class="body_capsule" size="0.05 0.0353553" pos="0 0.025 -0.025" quat="0.92388 0.382683 0 0"/>
        <geom name="left_hip_pitch_link_visual" class="visual" type="mesh" mesh="left_hip_pitch_link.STL"/>
        <body name="left_hip_roll_link" pos="0 0.051265 -0.051265">
          <inertial pos="0.01525 -0.00017964 -0.061059" mass="0.83528" diaginertia="0.00054401 0.00063585 0.00038113"/>
          <joint name="left_hip_roll_joint" class="motor" pos="0 0 0" axis="1 0 0" range="-0.785398 0.785398" armature="0.01"/>
          <geom name="left_hip_roll_link_visual" class="visual" type="mesh" mesh="left_hip_roll_link.STL"/>
          <body name="left_hip_yaw_link" pos="0 0 -0.09275">
            <inertial pos="7.0761e-05 0.00031363 -0.11496" mass="1.2782" diaginertia="0.0024302 0.0025065 0.0007566"/>
            <joint name="left_hip_yaw_joint" class="motor" pos="0 0 0" axis="0 0 -1" range="-0.785398 0.785398" armature="0.01"/>
            <geom name="left_hip_yaw_link_collision" class="body_capsule" size="0.05 0.02" pos="0 0 -0.03"/>
            <geom name="left_hip_yaw_link_visual" class="visual" type="mesh" mesh="left_hip_yaw_link.STL"/>
            <body name="left_knee_link" pos="0 0 -0.15489">
              <inertial pos="-0.0025212 0.00051084 -0.10659" mass="2.2481" diaginertia="0.0093797 0.0095623 0.0023403"/>
              <joint name="left_knee_joint" class="motor" pos="0 0 0" axis="0 1 0" range="0 1.5" armature="0.01"/>
              <geom name="left_knee_link_collision" class="body_capsule" size="0.05 0.125" pos="0 0 -0.125"/>
              <geom name="left_knee_link_visual" class="visual" type="mesh" mesh="left_knee_link.STL"/>
              <body name="left_ankle_pitch_link" pos="0 0 -0.29466">
                <inertial pos="-0.0011784 -2.4418e-08 -0.0061736" mass="0.27369" diaginertia="6.4443e-05 8.1172e-05 4.7493e-05"/>
                <joint name="left_ankle_pitch_joint" class="motor" pos="0 0 0" axis="0 1 0" range="-0.349066 0.5" armature="0.01"/>
                <geom name="left_ankle_pitch_link_visual" class="visual" type="mesh" mesh="left_ankle_pitch_link.STL"/>
                <body name="left_ankle_roll_link" pos="-0.0015 0 -0.01">
                  <inertial pos="0.081381 -0.00033806 -0.015509" mass="0.61291" diaginertia="0.00031968 0.00045036 0.00070504"/>
                  <joint name="left_ankle_roll_joint" class="motor" pos="0 0 0" axis="-1 0 0" range="-0.1 0.1" armature="0.01"/>
                  <geom name="left_ankle_roll_link_visual" class="visual" type="mesh" mesh="left_ankle_roll_link.STL"/>
                  <geom name="left_foot1_collision" class="foot_capsule" size="0.01 0.0152069" pos="0.075 -0.0325 -0.022" quat="0.707107 -0.116248 -0.697486 0"/>
                  <geom name="left_foot2_collision" class="foot_capsule" size="0.01 0.0625" pos="0.0275 -0.015 -0.022" quat="0.707107 0 -0.707107 0"/>
                  <geom name="left_foot3_collision" class="foot_capsule" size="0.01 0.0625" pos="0.0275 0 -0.022" quat="0.707107 0 -0.707107 0"/>
                  <geom name="left_foot4_collision" class="foot_capsule" size="0.01 0.0625" pos="0.0275 0.015 -0.022" quat="0.707107 0 -0.707107 0"/>
                  <geom name="left_foot6_collision" class="foot_capsule" size="0.01 0.0450694" pos="0.045 0.0325 -0.022" quat="0.707107 0.0392232 -0.706018 0"/>
                  <site name="left_foot" pos="0.04 0 -0.025"/>
                  <body name="left_toe_link" pos="0.10253 -0.0043664 -0.0067324">
                    <inertial pos="0.0320168 0.000718249 -0.0141313" mass="0.112221" diaginertia="5.53519e-05 3.65131e-05 8.5403e-05"/>
                    <joint name="left_toe_joint" pos="0 0 0" axis="0.010532 0.999945 0" solreflimit="0.005" solimplimit="0.99 0.999" stiffness="4.5" limited="true" range="-1.047 0" margin="0.01" armature="0.01" damping="0.5" frictionloss="0.02"/>
                    <geom name="left_toe_link_visual" class="visual" type="mesh" mesh="left_toe_link.STL"/>
                    <geom name="left_toe1_collision" class="foot_capsule" size="0.01 0.015" pos="0.025 -0.03 -0.018" quat="0.707107 0 -0.707107 0"/>
                    <geom name="left_toe2_collision" class="foot_capsule" size="0.01 0.0225" pos="0.0325 -0.015 -0.018" quat="0.707107 0 -0.707107 0"/>
                    <geom name="left_toe3_collision" class="foot_capsule" size="0.01 0.025" pos="0.035 0 -0.018" quat="0.707107 0 -0.707107 0"/>
                    <geom name="left_toe4_collision" class="foot_capsule" size="0.01 0.0225" pos="0.0325 0.02 -0.018" quat="0.707107 0 -0.707107 0"/>
                    <geom name="left_toe5_collision" class="foot_capsule" size="0.01 0.015" pos="0.025 0.04 -0.018" quat="0.707107 0 -0.707107 0"/>
                  </body>
                </body>
              </body>
            </body>
          </body>
        </body>
      </body>
      <body name="right_hip_pitch_link" pos="0 -0.056569 -0.10543">
        <inertial pos="0.0032901 -0.045581 -0.045581" mass="0.92565" diaginertia="0.00053984 0.00066418 0.00066418"/>
        <joint name="right_hip_pitch_joint" class="motor" pos="0 0 0" axis="0 -0.707107 -0.707107" range="-1 2.0944" armature="0.01"/>
        <geom name="right_hip_pitch_link_collision" class="body_capsule" size="0.05 0.0353553" pos="0 -0.025 -0.025" quat="0.92388 -0.382683 0 0"/>
        <geom name="right_hip_pitch_link_visual" class="visual" type="mesh" mesh="right_hip_pitch_link.STL"/>
        <body name="right_hip_roll_link" pos="0 -0.051265 -0.051265">
          <inertial pos="0.01525 0.0001796 -0.061059" mass="0.83528" diaginertia="0.00054401 0.00063584 0.00038113"/>
          <joint name="right_hip_roll_joint" class="motor" pos="0 0 0" axis="1 0 0" range="-0.785398 0.785398" armature="0.01"/>
          <geom name="right_hip_roll_link_visual" class="visual" type="mesh" mesh="right_hip_roll_link.STL"/>
          <body name="right_hip_yaw_link" pos="0 0 -0.09275">
            <inertial pos="7.1067e-05 -0.00031339 -0.11496" mass="1.2782" diaginertia="0.0024302 0.0025065 0.0007566"/>
            <joint name="right_hip_yaw_joint" class="motor" pos="0 0 0" axis="0 0 -1" range="-0.785398 0.785398" armature="0.01"/>
            <geom name="right_hip_yaw_link_collision" class="body_capsule" size="0.05 0.02" pos="0 0 -0.03"/>
            <geom name="right_hip_yaw_link_visual" class="visual" type="mesh" mesh="right_hip_yaw_link.STL"/>
            <body name="right_knee_link" pos="0 0 -0.15489">
              <inertial pos="-0.0025213 -0.00051098 -0.10659" mass="2.2481" diaginertia="0.0093796 0.0095623 0.0023403"/>
              <joint name="right_knee_joint" class="motor" pos="0 0 0" axis="0 -1 0" range="-1.5 0" armature="0.01"/>
              <geom name="right_knee_link_collision" class="body_capsule" size="0.05 0.125" pos="0 0 -0.125"/>
              <geom name="right_knee_link_visual" class="visual" type="mesh" mesh="right_knee_link.STL"/>
              <body name="right_ankle_pitch_link" pos="0 0 -0.29466">
                <inertial pos="-0.0011784 5.9726e-08 -0.0061735" mass="0.27369" diaginertia="6.4442e-05 8.1171e-05 4.7493e-05"/>
                <joint name="right_ankle_pitch_joint" class="motor" pos="0 0 0" axis="0 -1 0" range="-0.5 0.349066" armature="0.01"/>
                <geom name="right_ankle_pitch_link_visual" class="visual" type="mesh" mesh="right_ankle_pitch_link.STL"/>
                <body name="right_ankle_roll_link" pos="-0.0015 0 -0.01">
                  <inertial pos="0.081347 0.00027474 -0.015509" mass="0.61291" diaginertia="0.0003197 0.00045029 0.00070498"/>
                  <joint name="right_ankle_roll_joint" class="motor" pos="0 0 0" axis="-1 0 0" range="-0.1 0.1" armature="0.01"/>
                  <geom name="right_ankle_roll_link_visual" class="visual" type="mesh" mesh="right_ankle_roll_link.STL"/>
                  <geom name="right_foot1_collision" class="foot_capsule" size="0.01 0.0450694" pos="0.045 -0.0325 -0.022" quat="0.707107 -0.0392232 -0.706018 0"/>
                  <geom name="right_foot2_collision" class="foot_capsule" size="0.01 0.0625" pos="0.0275 -0.015 -0.022" quat="0.707107 0 -0.707107 0"/>
                  <geom name="right_foot3_collision" class="foot_capsule" size="0.01 0.0625" pos="0.0275 0 -0.022" quat="0.707107 0 -0.707107 0"/>
                  <geom name="right_foot4_collision" class="foot_capsule" size="0.01 0.0625" pos="0.0275 0.015 -0.022" quat="0.707107 0 -0.707107 0"/>
                  <geom name="right_foot5_collision" class="foot_capsule" size="0.01 0.0152069" pos="0.075 0.0325 -0.022" quat="0.707107 0.116248 -0.697486 0"/>
                  <site name="right_foot" pos="0.04 0 -0.025"/>
                  <body name="right_toe_link" pos="0.10247 0.0042796 -0.0067324">
                    <inertial pos="0.0320142 -0.000816708 -0.0141309" mass="0.112222" diaginertia="5.53589e-05 3.65053e-05 8.54017e-05"/>
                    <joint name="right_toe_joint" pos="0 0 0" axis="0.00746852 -0.999972 0" solreflimit="0.005" solimplimit="0.99 0.999" stiffness="4.5" limited="true" range="0 1.047" margin="0.01" armature="0.01" damping="0.5" frictionloss="0.02"/>
                    <geom name="right_toe_link_visual" class="visual" type="mesh" mesh="right_toe_link.STL"/>
                    <geom name="right_toe1_collision" class="foot_capsule" size="0.01 0.015" pos="0.025 -0.04 -0.018" quat="0.707107 0 -0.707107 0"/>
                    <geom name="right_toe2_collision" class="foot_capsule" size="0.01 0.0225" pos="0.0325 -0.02 -0.018" quat="0.707107 0 -0.707107 0"/>
                    <geom name="right_toe3_collision" class="foot_capsule" size="0.01 0.025" pos="0.035 0 -0.018" quat="0.707107 0 -0.707107 0"/>
                    <geom name="right_toe4_collision" class="foot_capsule" size="0.01 0.0225" pos="0.0325 0.015 -0.018" quat="0.707107 0 -0.707107 0"/>
                    <geom name="right_toe5_collision" class="foot_capsule" size="0.01 0.015" pos="0.025 0.03 -0.018" quat="0.707107 0 -0.707107 0"/>
                  </body>
                </body>
              </body>
            </body>
          </body>
        </body>
      </body>
    </body>
  </worldbody>

  <contact>
    <exclude body1="pelvis_link" body2="left_hip_pitch_link"/>
    <exclude body1="pelvis_link" body2="right_hip_pitch_link"/>
    <exclude body1="left_hip_pitch_link" body2="left_hip_roll_link"/>
    <exclude body1="left_hip_roll_link" body2="left_hip_yaw_link"/>
    <exclude body1="left_hip_yaw_link" body2="left_knee_link"/>
    <exclude body1="left_knee_link" body2="left_ankle_pitch_link"/>
    <exclude body1="left_ankle_pitch_link" body2="left_ankle_roll_link"/>
    <exclude body1="left_ankle_roll_link" body2="left_toe_link"/>
    <exclude body1="right_hip_pitch_link" body2="right_hip_roll_link"/>
    <exclude body1="right_hip_roll_link" body2="right_hip_yaw_link"/>
    <exclude body1="right_hip_yaw_link" body2="right_knee_link"/>
    <exclude body1="right_knee_link" body2="right_ankle_pitch_link"/>
    <exclude body1="right_ankle_pitch_link" body2="right_ankle_roll_link"/>
    <exclude body1="right_ankle_roll_link" body2="right_toe_link"/>
  </contact>

  <sensor>
    <gyro site="imu_in_pelvis" name="imu_ang_vel"/>
    <velocimeter site="imu_in_pelvis" name="imu_lin_vel"/>
    <framequat objtype="site" objname="imu_in_pelvis" name="imu_quat"/>
    <subtreeangmom body="pelvis_link" name="root_angmom"/>
  </sensor>
</mujoco>
